Workbook

Sheet Dados brutos
A1: Preço Médio - São Luís
B2: Total da Cesta | C2: Carne | D2: Leite | E2: Feijão | F2: Arroz | G2: Farinha | H2: Batata | I2: Tomate | J2: Pão | K2: Café | L2: Banana | M2: Açúcar | N2: Óleo | O2: Manteiga
A3: 01-2016 | B3: 351.17 | C3: 20.84 | D3: 3.34 | E3: 5.59 | F3: 3.02 | G3: 3.81 | I3: 6.28 | J3: 7.79 | K3: 16.32 | L3: 4.38 | M3: 2.99 | N3: 3.71 | O3: 23.15
A4: 02-2016 | B4: 355.29 | C4: 20.99 | D4: 3.38 | E4: 5.85 | F4: 3.12 | G4: 4.03 | I4: 5.94 | J4: 7.65 | K4: 16.74 | L4: 4.92 | M4: 3.24 | N4: 3.93 | O4: 24.2
A5: 03-2016 | B5: 356.56 | C5: 21.03 | D5: 3.49 | E5: 6.2 | F5: 3.08 | G5: 4.5 | I5: 5.2 | J5: 7.65 | K5: 16.75 | L5: 5.51 | M5: 3.3 | N5: 4.05 | O5: 26.5
A6: 04-2016 | B6: 357.11 | C6: 21.05 | D6: 3.61 | E6: 6.45 | F6: 3.06 | G6: 4.91 | I6: 4.5 | J6: 7.7 | K6: 17.15 | L6: 5.97 | M6: 3.37 | N6: 4.05 | O6: 28.87
A7: 05-2016 | B7: 360.12 | C7: 21 | D7: 3.62 | E7: 6.86 | F7: 3.11 | G7: 5.07 | I7: 4.23 | J7: 8.02 | K7: 17.92 | L7: 5.96 | M7: 3.28 | N7: 4.04 | O7: 31.7
A8: 06-2016 | B8: 368.49 | C8: 20.78 | D8: 3.91 | E8: 10.05 | F8: 3.13 | G8: 5.14 | I8: 3.84 | J8: 7.94 | K8: 18.05 | L8: 5.61 | M8: 3.26 | N8: 3.92 | O8: 32.9
A9: 07-2016 | B9: 384.63 | C9: 20.48 | D9: 4.48 | E9: 12.68 | F9: 3.16 | G9: 5.1 | I9: 3.98 | J9: 8.07 | K9: 18.55 | L9: 5.45 | M9: 3.28 | N9: 3.8 | O9: 34.11
A10: 08-2016 | B10: 386.2 | C10: 20.42 | D10: 4.6 | E10: 12.16 | F10: 3.3 | G10: 5.21 | I10: 4.08 | J10: 8.07 | K10: 18.95 | L10: 5.56 | M10: 3.31 | N10: 3.68 | O10: 34.8
A11: 09-2016 | B11: 383.04 | C11: 20.23 | D11: 4.57 | E11: 11.64 | F11: 3.4 | G11: 5.29 | I11: 3.99 | J11: 8.07 | K11: 19.69 | L11: 5.58 | M11: 3.27 | N11: 3.66 | O11: 35.41
A12: 10-2016 | B12: 386.41 | C12: 20.71 | D12: 4.48 | E12: 11.21 | F12: 3.48 | G12: 5.4 | I12: 4.36 | J12: 8.07 | K12: 19.71 | L12: 5.37 | M12: 3.31 | N12: 3.66 | O12: 35.51
A13: 11-2016 | B13: 371.42 | C13: 20.81 | D13: 4.21 | E13: 9.6 | F13: 3.6 | G13: 5.68 | I13: 3.84 | J13: 8.07 | K13: 19.95 | L13: 5.13 | M13: 3.6 | N13: 3.76 | O13: 34.37
A14: 12-2016 | B14: 356.07 | C14: 20.67 | D14: 4.02 | E14: 8.05 | F14: 3.5 | G14: 5.81 | I14: 3.39 | J14: 8.01 | K14: 20.24 | L14: 4.89 | M14: 3.59 | N14: 3.88 | O14: 35.37
... A42: 04-2019 | B42: 423.66 | C42: 21.74 | D42: 3.82 | E42: 8.42 | F42: 3.19 | G42: 3.97 | I42: 8.07 | J42: 8.83 | K42: 17.5 | L42: 5.75 | M42: 2.78 | N42: 3.88 | O42: 41.61
A43: 05-2019
A44: 06-2019
A45: 07-2019
A46: 08-2019
A47: 09-2019
A48: 10-2019
A49: 11-2019
A50: 12-2019
A51: 01-2020
A52: 02-2020
A53: 03-2020
A54: 04-2020
... A113: 03-2025
A114: 04-2025 | B114: 671.77 | C114: 41.09 | D114: 5.99 | E114: 6.28 | F114: 5.56 | G114: 9.07 | I114: 9.08 | J114: 18.44 | K114: 61.9 | L114: 9.09 | M114: 4.02 | N114: 8.77 | O114: 64.33
A115: 05-2025 | B115: 667.98 | C115: 41.23 | D115: 6.05 | E115: 6.19 | F115: 5.04 | G115: 8.76 | I115: 8.87 | J115: 18.52 | K115: 63.92 | L115: 9.36 | M115: 3.79 | N115: 8.01 | O115: 63.39
A116: 06-2025 | B116: 655.32 | C116: 39.96 | D116: 5.88 | E116: 6.11 | F116: 4.87 | G116: 8.36 | I116: 8.55 | J116: 18.57 | K116: 63.61 | L116: 9.16 | M116: 3.76 | N116: 8.14 | O116: 65.19
A117: 07-2025 | B117: 664.52 | C117: 39.98 | D117: 5.85 | E117: 6.13 | F117: 4.69 | G117: 7.77 | I117: 9.36 | J117: 18.51 | K117: 62.46 | L117: 9.33 | M117: 3.87 | N117: 8.44 | O117: 66.1
A118: 08-2025 | B118: 644.21 | C118: 39.98 | D118: 5.72 | E118: 5.81 | F118: 4.56 | G118: 8.06 | I118: 8.25 | J118: 18.52 | K118: 62.4 | L118: 8.85 | M118: 3.79 | N118: 8.29 | O118: 64.46
A119: 09-2025 | B119: 623.92 | C119: 39.57 | D119: 5.59 | E119: 5.63 | F119: 4.37 | G119: 8.15 | I119: 7.05 | J119: 18.39 | K119: 65.58 | L119: 8.76 | M119: 3.78 | N119: 8.41 | O119: 62.3
A120: 10-2025 | B120: 643.31 | C120: 40.18 | D120: 5.6 | E120: 5.71 | F120: 4.34 | G120: 8.14 | I120: 8.14 | J120: 18.39 | K120: 64.98 | L120: 9.06 | M120: 3.74 | N120: 9.01 | O120: 63.29
A121: 11-2025 | B121: 626.82 | C121: 40.7 | D121: 5.3 | E121: 5.92 | F121: 4.14 | G121: 8.32 | I121: 6.82 | J121: 18.54 | K121: 61.67 | L121: 8.87 | M121: 3.67 | N121: 9.16 | O121: 62.78
A122: 12-2025 | B122: 629.43 | C122: 41.3 | D122: 5.21 | E122: 6.06 | F122: 4.1 | G122: 8.39 | I122: 7.1 | J122: 18.48 | K122: 61.34 | L122: 8.71 | M122: 3.67 | N122: 8.62 | O122: 60.9
A123: 01-2026 | B123: 625.86 | C123: 42.25 | D123: 5.2 | E123: 6.27 | F123: 4.04 | G123: 8.31 | I123: 6.62 | J123: 18.49 | K123: 61.09 | L123: 8.47 | M123: 3.65 | N123: 8.63 | O123: 60.02
A124: 02-2026 | B124: 630.01 | C124: 41.96 | D124: 5.2 | E124: 6.3 | F124: 4.04 | G124: 8.31 | I124: 6.94 | J124: 18.49 | K124: 59.38 | L124: 8.51 | M124: 3.65 | N124: 8.63 | O124: 62.3
A125: 03-2026 | B125: 634.26 | C125: 42.05 | D125: 5.22 | E125: 6.58 | F125: 4.15 | G125: 8.35 | I125: 6.99 | J125: 18.64 | K125: 66.16 | L125: 8.52 | M125: 3.66 | N125: 8.82 | O125: 59.79
...

Sheet Dados tratados
A1: Mês | B1: Ano | C1: Carne (R$/kg) | D1: Leite (R$/litro) | E1: Feijão (R$/kg) | F1: Arroz (R$/kg) | G1: Farinha de mandioca (R$/kg) | H1: Tomate (R$/kg) | I1: Pão francês (R$/kg) | J1: Café em pó (R$/kg) | K1: Banana (R$/dúzia) | L1: Açúcar (R$/kg) | M1: Óleo de soja (R$/900 ml) | N1: Manteiga (R$/kg) | O1: Custo da cesta (R$) | P1: Salário mínimo (R$) | Q1: % do salário mínimo
A2: 42370 | B2: =YEAR(A2) -> 2016 | C2: 20.84 | D2: 3.34 | E2: 5.59 | F2: 3.02 | G2: 3.81 | H2: 6.28 | I2: 7.79 | J2: 16.32 | K2: 4.38 | L2: 2.99 | M2: 3.71 | N2: 23.15 | O2: 351.17 | P2: =VLOOKUP(B2,Análises!$I$6:$J$11,2,FALSE()) -> 880 | Q2: =O2/P2 -> 0.39905682
A3: 42401 | B3: =YEAR(A3) -> 2016 | C3: 20.99 | D3: 3.38 | E3: 5.85 | F3: 3.12 | G3: 4.03 | H3: 5.94 | I3: 7.65 | J3: 16.74 | K3: 4.92 | L3: 3.24 | M3: 3.93 | N3: 24.2 | O3: 355.29 | P3: =VLOOKUP(B3,Análises!$I$6:$J$11,2,FALSE()) -> 880 | Q3: =O3/P3 -> 0.40373864
A4: 42430 | B4: =YEAR(A4) -> 2016 | C4: 21.03 | D4: 3.49 | E4: 6.2 | F4: 3.08 | G4: 4.5 | H4: 5.2 | I4: 7.65 | J4: 16.75 | K4: 5.51 | L4: 3.3 | M4: 4.05 | N4: 26.5 | O4: 356.56 | P4: =VLOOKUP(B4,Análises!$I$6:$J$11,2,FALSE()) -> 880 | Q4: =O4/P4 -> 0.40518182
A5: 42461 | B5: =YEAR(A5) -> 2016 | C5: 21.05 | D5: 3.61 | E5: 6.45 | F5: 3.06 | G5: 4.91 | H5: 4.5 | I5: 7.7 | J5: 17.15 | K5: 5.97 | L5: 3.37 | M5: 4.05 | N5: 28.87 | O5: 357.11 | P5: =VLOOKUP(B5,Análises!$I$6:$J$11,2,FALSE()) -> 880 | Q5: =O5/P5 -> 0.40580682
A6: 42491 | B6: =YEAR(A6) -> 2016 | C6: 21 | D6: 3.62 | E6: 6.86 | F6: 3.11 | G6: 5.07 | H6: 4.23 | I6: 8.02 | J6: 17.92 | K6: 5.96 | L6: 3.28 | M6: 4.04 | N6: 31.7 | O6: 360.12 | P6: =VLOOKUP(B6,Análises!$I$6:$J$11,2,FALSE()) -> 880 | Q6: =O6/P6 -> 0.40922727
A7: 42522 | B7: =YEAR(A7) -> 2016 | C7: 20.78 | D7: 3.91 | E7: 10.05 | F7: 3.13 | G7: 5.14 | H7: 3.84 | I7: 7.94 | J7: 18.05 | K7: 5.61 | L7: 3.26 | M7: 3.92 | N7: 32.9 | O7: 368.49 | P7: =VLOOKUP(B7,Análises!$I$6:$J$11,2,FALSE()) -> 880 | Q7: =O7/P7 -> 0.41873864
A8: 42552 | B8: =YEAR(A8) -> 2016 | C8: 20.48 | D8: 4.48 | E8: 12.68 | F8: 3.16 | G8: 5.1 | H8: 3.98 | I8: 8.07 | J8: 18.55 | K8: 5.45 | L8: 3.28 | M8: 3.8 | N8: 34.11 | O8: 384.63 | P8: =VLOOKUP(B8,Análises!$I$6:$J$11,2,FALSE()) -> 880 | Q8: =O8/P8 -> 0.43707955
A9: 42583 | B9: =YEAR(A9) -> 2016 | C9: 20.42 | D9: 4.6 | E9: 12.16 | F9: 3.3 | G9: 5.21 | H9: 4.08 | I9: 8.07 | J9: 18.95 | K9: 5.56 | L9: 3.31 | M9: 3.68 | N9: 34.8 | O9: 386.2 | P9: =VLOOKUP(B9,Análises!$I$6:$J$11,2,FALSE()) -> 880 | Q9: =O9/P9 -> 0.43886364
A10: 42614 | B10: =YEAR(A10) -> 2016 | C10: 20.23 | D10: 4.57 | E10: 11.64 | F10: 3.4 | G10: 5.29 | H10: 3.99 | I10: 8.07 | J10: 19.69 | K10: 5.58 | L10: 3.27 | M10: 3.66 | N10: 35.41 | O10: 383.04 | P10: =VLOOKUP(B10,Análises!$I$6:$J$11,2,FALSE()) -> 880 | Q10: =O10/P10 -> 0.43527273
A11: 42644 | B11: =YEAR(A11) -> 2016 | C11: 20.71 | D11: 4.48 | E11: 11.21 | F11: 3.48 | G11: 5.4 | H11: 4.36 | I11: 8.07 | J11: 19.71 | K11: 5.37 | L11: 3.31 | M11: 3.66 | N11: 35.51 | O11: 386.41 | P11: =VLOOKUP(B11,Análises!$I$6:$J$11,2,FALSE()) -> 880 | Q11: =O11/P11 -> 0.43910227
A12: 42675 | B12: =YEAR(A12) -> 2016 | C12: 20.81 | D12: 4.21 | E12: 9.6 | F12: 3.6 | G12: 5.68 | H12: 3.84 | I12: 8.07 | J12: 19.95 | K12: 5.13 | L12: 3.6 | M12: 3.76 | N12: 34.37 | O12: 371.42 | P12: =VLOOKUP(B12,Análises!$I$6:$J$11,2,FALSE()) -> 880 | Q12: =O12/P12 -> 0.42206818
A13: 42705 | B13: =YEAR(A13) -> 2016 | C13: 20.67 | D13: 4.02 | E13: 8.05 | F13: 3.5 | G13: 5.81 | H13: 3.39 | I13: 8.01 | J13: 20.24 | K13: 4.89 | L13: 3.59 | M13: 3.88 | N13: 35.37 | O13: 356.07 | P13: =VLOOKUP(B13,Análises!$I$6:$J$11,2,FALSE()) -> 880 | Q13: =O13/P13 -> 0.404625
... A59: 46266 | B59: =YEAR(A59) -> 2026 | C59: 45.36 | D59: 6.78 | E59: 8.97 | F59: 5.1 | G59: 8.73 | H59: 8.24 | I59: 19.45 | J59: 54.37 | K59: 8.71 | L59: 3.62 | M59: 8.69 | N59: 61.93 | O59: 692.94 | P59: =VLOOKUP(B59,Análises!$I$6:$J$11,2,FALSE()) -> 1621 | Q59: =O59/P59 -> 0.42747687

Sheet Análises
B1: Cesta básica em São Luís: 10 anos (2016–2026)
B2: Fonte: DIEESE, Pesquisa Nacional da Cesta Básica de Alimentos (preço médio, São Luís).
B4: Resumo da base | I4: Salário mínimo por ano
B5: Meses no arquivo do DIEESE | C5: =COUNTA('Dados brutos'!$A$3:$A$131) -> 129 | I5: Ano | J5: Salário mínimo (R$)
B6: Meses sem nenhum dado (removidos) | C6: =COUNTBLANK('Dados brutos'!$B$3:$B$131) -> 71 | D6: mai/2019 a mar/2025 | I6: 2016 | J6: 880
B7: Meses com dados (base tratada) | C7: =COUNT('Dados tratados'!$O$2:$O$59) -> 58 | I7: 2017 | J7: 937
B8: Primeiro mês | C8: =MIN('Dados tratados'!$A$2:$A$59) -> 42370 | I8: 2018 | J8: 954
B9: Último mês | C9: =MAX('Dados tratados'!$A$2:$A$59) -> 46266 | I9: 2019 | J9: 998
I10: 2025 | J10: 1518
B11: 1. Quanto a cesta subiu em 10 anos? | I11: 2026 | J11: 1621
B12: Indicador | C12: Primeiro mês | D12: Último mês | E12: Variação
B13: Mês | C13: =C8 -> 42370 | D13: =C9 -> 46266 | I13: Fonte: decretos do salário mínimo de cada ano.
B14: Custo da cesta (R$) | C14: =VLOOKUP(C$13,'Dados tratados'!$A$2:$Q$59,15,FALSE()) -> 351.17 | D14: =VLOOKUP(D$13,'Dados tratados'!$A$2:$Q$59,15,FALSE()) -> 692.94 | E14: =D14/C14-1 -> 0.97323234
B15: Salário mínimo (R$) | C15: =VLOOKUP(C$13,'Dados tratados'!$A$2:$Q$59,16,FALSE()) -> 880 | D15: =VLOOKUP(D$13,'Dados tratados'!$A$2:$Q$59,16,FALSE()) -> 1621 | E15: =D15/C15-1 -> 0.84204545
B16: % do salário mínimo | C16: =VLOOKUP(C$13,'Dados tratados'!$A$2:$Q$59,17,FALSE()) -> 0.39905682 | D16: =VLOOKUP(D$13,'Dados tratados'!$A$2:$Q$59,17,FALSE()) -> 0.42747687 | E16: =(D16-C16)*100 -> 2.8420048
B17: A cesta subiu mais que o salário? | C17: =IF(E14>E15,"Sim","Não") -> Sim
B20: 2. Como foi cada ano?
B21: Ano | C21: Meses com dados | D21: Custo médio (R$) | E21: % médio do salário | F21: Meses acima de 40% do salário | G21: Destaque
B22: 2016 | C22: =COUNTIF('Dados tratados'!$B$2:$B$59,B22) -> 12 | D22: =AVERAGEIF('Dados tratados'!$B$2:$B$59,B22,'Dados tratados'!$O$2:$O$59) -> 368.0425 | E22: =AVERAGEIF('Dados tratados'!$B$2:$B$59,B22,'Dados tratados'!$Q$2:$Q$59) -> 0.41823011 | F22: =COUNTIFS('Dados tratados'!$B$2:$B$59,B22,'Dados tratados'!$Q$2:$Q$59,">"&0.4) -> 11 | G22: =IF(E22=MAX($E$22:$E$27),"Ano mais pesado",IF(E22=MIN($E$22:$E$27),"Ano mais leve",""))
B23: 2017 | C23: =COUNTIF('Dados tratados'!$B$2:$B$59,B23) -> 12 | D23: =AVERAGEIF('Dados tratados'!$B$2:$B$59,B23,'Dados tratados'!$O$2:$O$59) -> 352.63 | E23: =AVERAGEIF('Dados tratados'!$B$2:$B$59,B23,'Dados tratados'!$Q$2:$Q$59) -> 0.37633938 | F23: =COUNTIFS('Dados tratados'!$B$2:$B$59,B23,'Dados tratados'!$Q$2:$Q$59,">"&0.4) -> 0 | G23: =IF(E23=MAX($E$22:$E$27),"Ano mais pesado",IF(E23=MIN($E$22:$E$27),"Ano mais leve",""))
B24: 2018 | C24: =COUNTIF('Dados tratados'!$B$2:$B$59,B24) -> 12 | D24: =AVERAGEIF('Dados tratados'!$B$2:$B$59,B24,'Dados tratados'!$O$2:$O$59) -> 345.905 | E24: =AVERAGEIF('Dados tratados'!$B$2:$B$59,B24,'Dados tratados'!$Q$2:$Q$59) -> 0.36258386 | F24: =COUNTIFS('Dados tratados'!$B$2:$B$59,B24,'Dados tratados'!$Q$2:$Q$59,">"&0.4) -> 0 | G24: =IF(E24=MAX($E$22:$E$27),"Ano mais pesado",IF(E24=MIN($E$22:$E$27),"Ano mais leve","")) -> Ano mais leve
B25: 2019 | C25: =COUNTIF('Dados tratados'!$B$2:$B$59,B25) -> 4 | D25: =AVERAGEIF('Dados tratados'!$B$2:$B$59,B25,'Dados tratados'!$O$2:$O$59) -> 385.4775 | E25: =AVERAGEIF('Dados tratados'!$B$2:$B$59,B25,'Dados tratados'!$Q$2:$Q$59) -> 0.38625 | F25: =COUNTIFS('Dados tratados'!$B$2:$B$59,B25,'Dados tratados'!$Q$2:$Q$59,">"&0.4) -> 1 | G25: =IF(E25=MAX($E$22:$E$27),"Ano mais pesado",IF(E25=MIN($E$22:$E$27),"Ano mais leve",""))
B26: 2025 | C26: =COUNTIF('Dados tratados'!$B$2:$B$59,B26) -> 9 | D26: =AVERAGEIF('Dados tratados'!$B$2:$B$59,B26,'Dados tratados'!$O$2:$O$59) -> 647.47556 | E26: =AVERAGEIF('Dados tratados'!$B$2:$B$59,B26,'Dados tratados'!$Q$2:$Q$59) -> 0.42653199 | F26: =COUNTIFS('Dados tratados'!$B$2:$B$59,B26,'Dados tratados'!$Q$2:$Q$59,">"&0.4) -> 9 | G26: =IF(E26=MAX($E$22:$E$27),"Ano mais pesado",IF(E26=MIN($E$22:$E$27),"Ano mais leve","")) -> Ano mais pesado
B27: 2026 | C27: =COUNTIF('Dados tratados'!$B$2:$B$59,B27) -> 9 | D27: =AVERAGEIF('Dados tratados'!$B$2:$B$59,B27,'Dados tratados'!$O$2:$O$59) -> 649.63 | E27: =AVERAGEIF('Dados tratados'!$B$2:$B$59,B27,'Dados tratados'!$Q$2:$Q$59) -> 0.40075879 | F27: =COUNTIFS('Dados tratados'!$B$2:$B$59,B27,'Dados tratados'!$Q$2:$Q$59,">"&0.4) -> 5 | G27: =IF(E27=MAX($E$22:$E$27),"Ano mais pesado",IF(E27=MIN($E$22:$E$27),"Ano mais leve",""))
B28: Total | C28: =SUM(C22:C27) -> 58 | F28: =SUM(F22:F27) -> 26
B29: 2019 tem só jan–abr e 2025 só abr–dez: o arquivo do DIEESE não tem dados de São Luís de mai/2019 a mar/2025.
B31: 3. Qual alimento mais encareceu em 10 anos?
B32: Alimento | C32: Preço no primeiro mês (R$) | D32: Preço no último mês (R$) | E32: Variação | F32: Comparado ao salário
B33: Café em pó | C33: =VLOOKUP($C$13,'Dados tratados'!$A$2:$Q$59,10,FALSE()) -> 16.32 | D33: =VLOOKUP($D$13,'Dados tratados'!$A$2:$Q$59,10,FALSE()) -> 54.37 | E33: =D33/C33-1 -> 2.3314951 | F33: =IF(E33>$E$15,"subiu mais que o salário","subiu menos que o salário") -> subiu mais que o salário
B34: Manteiga | C34: =VLOOKUP($C$13,'Dados tratados'!$A$2:$Q$59,14,FALSE()) -> 23.15 | D34: =VLOOKUP($D$13,'Dados tratados'!$A$2:$Q$59,14,FALSE()) -> 61.93 | E34: =D34/C34-1 -> 1.675162 | F34: =IF(E34>$E$15,"subiu mais que o salário","subiu menos que o salário") -> subiu mais que o salário
B35: Pão francês | C35: =VLOOKUP($C$13,'Dados tratados'!$A$2:$Q$59,9,FALSE()) -> 7.79 | D35: =VLOOKUP($D$13,'Dados tratados'!$A$2:$Q$59,9,FALSE()) -> 19.45 | E35: =D35/C35-1 -> 1.4967908 | F35: =IF(E35>$E$15,"subiu mais que o salário","subiu menos que o salário") -> subiu mais que o salário
B36: Óleo de soja | C36: =VLOOKUP($C$13,'Dados tratados'!$A$2:$Q$59,13,FALSE()) -> 3.71 | D36: =VLOOKUP($D$13,'Dados tratados'!$A$2:$Q$59,13,FALSE()) -> 8.69 | E36: =D36/C36-1 -> 1.3423181 | F36: =IF(E36>$E$15,"subiu mais que o salário","subiu menos que o salário") -> subiu mais que o salário
B37: Farinha de mandioca | C37: =VLOOKUP($C$13,'Dados tratados'!$A$2:$Q$59,7,FALSE()) -> 3.81 | D37: =VLOOKUP($D$13,'Dados tratados'!$A$2:$Q$59,7,FALSE()) -> 8.73 | E37: =D37/C37-1 -> 1.2913386 | F37: =IF(E37>$E$15,"subiu mais que o salário","subiu menos que o salário") -> subiu mais que o salário
B38: Carne bovina | C38: =VLOOKUP($C$13,'Dados tratados'!$A$2:$Q$59,3,FALSE()) -> 20.84 | D38: =VLOOKUP($D$13,'Dados tratados'!$A$2:$Q$59,3,FALSE()) -> 45.36 | E38: =D38/C38-1 -> 1.1765835 | F38: =IF(E38>$E$15,"subiu mais que o salário","subiu menos que o salário") -> subiu mais que o salário
B39: Leite integral | C39: =VLOOKUP($C$13,'Dados tratados'!$A$2:$Q$59,4,FALSE()) -> 3.34 | D39: =VLOOKUP($D$13,'Dados tratados'!$A$2:$Q$59,4,FALSE()) -> 6.78 | E39: =D39/C39-1 -> 1.0299401 | F39: =IF(E39>$E$15,"subiu mais que o salário","subiu menos que o salário") -> subiu mais que o salário
B40: Banana | C40: =VLOOKUP($C$13,'Dados tratados'!$A$2:$Q$59,11,FALSE()) -> 4.38 | D40: =VLOOKUP($D$13,'Dados tratados'!$A$2:$Q$59,11,FALSE()) -> 8.71 | E40: =D40/C40-1 -> 0.98858447 | F40: =IF(E40>$E$15,"subiu mais que o salário","subiu menos que o salário") -> subiu mais que o salário
B41: Arroz agulhinha | C41: =VLOOKUP($C$13,'Dados tratados'!$A$2:$Q$59,6,FALSE()) -> 3.02 | D41: =VLOOKUP($D$13,'Dados tratados'!$A$2:$Q$59,6,FALSE()) -> 5.1 | E41: =D41/C41-1 -> 0.68874172 | F41: =IF(E41>$E$15,"subiu mais que o salário","subiu menos que o salário") -> subiu menos que o salário
B42: Feijão carioca | C42: =VLOOKUP($C$13,'Dados tratados'!$A$2:$Q$59,5,FALSE()) -> 5.59 | D42: =VLOOKUP($D$13,'Dados tratados'!$A$2:$Q$59,5,FALSE()) -> 8.97 | E42: =D42/C42-1 -> 0.60465116 | F42: =IF(E42>$E$15,"subiu mais que o salário","subiu menos que o salário") -> subiu menos que o salário
B43: Tomate | C43: =VLOOKUP($C$13,'Dados tratados'!$A$2:$Q$59,8,FALSE()) -> 6.28 | D43: =VLOOKUP($D$13,'Dados tratados'!$A$2:$Q$59,8,FALSE()) -> 8.24 | E43: =D43/C43-1 -> 0.31210191 | F43: =IF(E43>$E$15,"subiu mais que o salário","subiu menos que o salário") -> subiu menos que o salário
B44: Açúcar cristal | C44: =VLOOKUP($C$13,'Dados tratados'!$A$2:$Q$59,12,FALSE()) -> 2.99 | D44: =VLOOKUP($D$13,'Dados tratados'!$A$2:$Q$59,12,FALSE()) -> 3.62 | E44: =D44/C44-1 -> 0.21070234 | F44: =IF(E44>$E$15,"subiu mais que o salário","subiu menos que o salário") -> subiu menos que o salário
...
